Unable to init server: Could not connect: Connection refused
Unable to init server: Could not connect: Connection refused

(transfer_attacks.py:1429027): Gdk-CRITICAL **: 17:20:37.317: gdk_cursor_new_for_display: assertion 'GDK_IS_DISPLAY (display)' failed
Working on OSSA Attacks...
Traceback (most recent call last):
  File "transfer_attacks.py", line 52, in <module>
    ossa_accs  = attacker.get_OSSA_attack_accuracy(epsilons = epsilons)                                          
  File "/home/naddeok5/FIM/adversarial_attacks.py", line 157, in get_OSSA_attack_accuracy
    eig_val_max, eig_vec_max = self.get_eigensystem(fisher, max_only = True)
  File "/home/naddeok5/FIM/adversarial_attacks.py", line 123, in get_eigensystem
    eig_values, eig_vectors = torch.symeig(tensor, eigenvectors = True, upper = True)       
KeyboardInterrupt
